2025-02-28 17:13:14,330 - diamond.<module> - INFO - Starting logger.
2025-02-28 17:13:14,996 - emod.start - INFO - Starting Job Manager.
2025-02-28 17:13:14,999 - cron.run - INFO - Starting Cron Daemon.
2025-02-28 17:13:19,395 - trait_notifiers._log_exception - ERROR - Exception occurred in traits notification handler for object: <measurements.confocal.Confocal object at 0x0000028FCD3089F0>, trait: x, old value: 172.0, new value: 170.2970297029703
Traceback (most recent call last):
  File "D:\Anaconda\install\envs\pi3\Lib\site-packages\traits\trait_notifiers.py", line 525, in _dispatch_change_event
    self.dispatch(handler, *args)
  File "D:\Anaconda\install\envs\pi3\Lib\site-packages\traits\trait_notifiers.py", line 487, in dispatch
    handler(*args)
  File "C:\Users\yy3\pi3-mini\measurements\confocal.py", line 122, in _set_scanner_position
    scanner.setPosition(self.x, self.y, self.z)
  File "C:\Users\yy3\pi3-mini\hardware\nidaq.py", line 442, in setPosition
    self.WriteAO(self.PosToVolt((x, y, z)), start=True)
  File "C:\Users\yy3\pi3-mini\hardware\nidaq.py", line 278, in WriteAO
    CHK( dll.DAQmxWriteAnalogF64( self.AOTask,
         ^^^^^^^^^^^^^^^^^^^^^^^^^^^^^^^^^^^^^
  File "<string>", line 2, in function
  File "D:\Anaconda\install\envs\pi3\Lib\site-packages\PyDAQmx\DAQmxFunctions.py", line 62, in mafunction
    raise exception_class(errBuff.value.decode("utf-8"), f.__name__)
PyDAQmx.DAQmxFunctions.PALResourceReservedError: The specified resource is reserved. The operation could not be completed as specified.
Task Name: _unnamedTask<2>

Status Code: -50103
 in function DAQmxWriteAnalogF64
2025-02-28 17:13:19,418 - trait_notifiers._log_exception - ERROR - Exception occurred in traits notification handler for object: <measurements.confocal.Confocal object at 0x0000028FCD3089F0>, trait: y, old value: 172.0, new value: 170.2970297029703
Traceback (most recent call last):
  File "D:\Anaconda\install\envs\pi3\Lib\site-packages\traits\trait_notifiers.py", line 525, in _dispatch_change_event
    self.dispatch(handler, *args)
  File "D:\Anaconda\install\envs\pi3\Lib\site-packages\traits\trait_notifiers.py", line 487, in dispatch
    handler(*args)
  File "C:\Users\yy3\pi3-mini\measurements\confocal.py", line 122, in _set_scanner_position
    scanner.setPosition(self.x, self.y, self.z)
  File "C:\Users\yy3\pi3-mini\hardware\nidaq.py", line 442, in setPosition
    self.WriteAO(self.PosToVolt((x, y, z)), start=True)
  File "C:\Users\yy3\pi3-mini\hardware\nidaq.py", line 278, in WriteAO
    CHK( dll.DAQmxWriteAnalogF64( self.AOTask,
         ^^^^^^^^^^^^^^^^^^^^^^^^^^^^^^^^^^^^^
  File "<string>", line 2, in function
  File "D:\Anaconda\install\envs\pi3\Lib\site-packages\PyDAQmx\DAQmxFunctions.py", line 62, in mafunction
    raise exception_class(errBuff.value.decode("utf-8"), f.__name__)
PyDAQmx.DAQmxFunctions.PALResourceReservedError: The specified resource is reserved. The operation could not be completed as specified.
Task Name: _unnamedTask<2>

Status Code: -50103
 in function DAQmxWriteAnalogF64
2025-02-28 17:15:43,248 - diamond.<module> - INFO - Starting logger.
2025-02-28 17:15:43,927 - emod.start - INFO - Starting Job Manager.
2025-02-28 17:15:43,928 - cron.run - INFO - Starting Cron Daemon.
2025-02-28 17:15:46,639 - trait_notifiers._log_exception - ERROR - Exception occurred in traits notification handler for object: <measurements.confocal.Confocal object at 0x000002B61BD6F4C0>, trait: x, old value: 172.0, new value: 170.2970297029703
Traceback (most recent call last):
  File "D:\Anaconda\install\envs\pi3\Lib\site-packages\traits\trait_notifiers.py", line 525, in _dispatch_change_event
    self.dispatch(handler, *args)
  File "D:\Anaconda\install\envs\pi3\Lib\site-packages\traits\trait_notifiers.py", line 487, in dispatch
    handler(*args)
  File "C:\Users\yy3\pi3-mini\measurements\confocal.py", line 122, in _set_scanner_position
    scanner.setPosition(self.x, self.y, self.z)
  File "C:\Users\yy3\pi3-mini\hardware\nidaq.py", line 442, in setPosition
    self.WriteAO(self.PosToVolt((x, y, z)), start=True)
  File "C:\Users\yy3\pi3-mini\hardware\nidaq.py", line 278, in WriteAO
    CHK( dll.DAQmxWriteAnalogF64( self.AOTask,
         ^^^^^^^^^^^^^^^^^^^^^^^^^^^^^^^^^^^^^
  File "<string>", line 2, in function
  File "D:\Anaconda\install\envs\pi3\Lib\site-packages\PyDAQmx\DAQmxFunctions.py", line 62, in mafunction
    raise exception_class(errBuff.value.decode("utf-8"), f.__name__)
PyDAQmx.DAQmxFunctions.PALResourceReservedError: The specified resource is reserved. The operation could not be completed as specified.
Task Name: _unnamedTask<2>

Status Code: -50103
 in function DAQmxWriteAnalogF64
2025-02-28 17:15:46,644 - trait_notifiers._log_exception - ERROR - Exception occurred in traits notification handler for object: <measurements.confocal.Confocal object at 0x000002B61BD6F4C0>, trait: y, old value: 172.0, new value: 170.2970297029703
Traceback (most recent call last):
  File "D:\Anaconda\install\envs\pi3\Lib\site-packages\traits\trait_notifiers.py", line 525, in _dispatch_change_event
    self.dispatch(handler, *args)
  File "D:\Anaconda\install\envs\pi3\Lib\site-packages\traits\trait_notifiers.py", line 487, in dispatch
    handler(*args)
  File "C:\Users\yy3\pi3-mini\measurements\confocal.py", line 122, in _set_scanner_position
    scanner.setPosition(self.x, self.y, self.z)
  File "C:\Users\yy3\pi3-mini\hardware\nidaq.py", line 442, in setPosition
    self.WriteAO(self.PosToVolt((x, y, z)), start=True)
  File "C:\Users\yy3\pi3-mini\hardware\nidaq.py", line 278, in WriteAO
    CHK( dll.DAQmxWriteAnalogF64( self.AOTask,
         ^^^^^^^^^^^^^^^^^^^^^^^^^^^^^^^^^^^^^
  File "<string>", line 2, in function
  File "D:\Anaconda\install\envs\pi3\Lib\site-packages\PyDAQmx\DAQmxFunctions.py", line 62, in mafunction
    raise exception_class(errBuff.value.decode("utf-8"), f.__name__)
PyDAQmx.DAQmxFunctions.PALResourceReservedError: The specified resource is reserved. The operation could not be completed as specified.
Task Name: _unnamedTask<2>

Status Code: -50103
 in function DAQmxWriteAnalogF64
2025-02-28 17:16:48,336 - diamond.<module> - INFO - Starting logger.
2025-02-28 17:16:49,042 - emod.start - INFO - Starting Job Manager.
2025-02-28 17:16:49,043 - cron.run - INFO - Starting Cron Daemon.
2025-02-28 17:20:24,232 - diamond.<module> - INFO - Starting logger.
2025-02-28 17:20:24,899 - emod.start - INFO - Starting Job Manager.
2025-02-28 17:20:24,900 - cron.run - INFO - Starting Cron Daemon.
2025-02-28 17:21:32,745 - pulsed._run - ERROR - Something went wrong in pulsed loop.
Traceback (most recent call last):
  File "C:\Users\yy3\pi3-mini\measurements\pulsed.py", line 184, in _run
    self.apply_parameters()
  File "C:\Users\yy3\pi3-mini\measurements\rabi.py", line 32, in apply_parameters
    Pulsed.apply_parameters(self)
  File "C:\Users\yy3\pi3-mini\measurements\pulsed.py", line 156, in apply_parameters
    sequence = self.generate_sequence()
               ^^^^^^^^^^^^^^^^^^^^^^^^
  File "C:\Users\yy3\pi3-mini\measurements\rabi.py", line 67, in generate_sequence
    sequence = [(['sync'], sync_time)]
                           ^^^^^^^^^
NameError: name 'sync_time' is not defined
2025-02-28 17:22:22,780 - diamond.<module> - INFO - Starting logger.
2025-02-28 17:22:23,481 - emod.start - INFO - Starting Job Manager.
2025-02-28 17:22:23,482 - cron.run - INFO - Starting Cron Daemon.
2025-02-28 17:22:33,668 - pulsed._run - ERROR - Something went wrong in pulsed loop.
Traceback (most recent call last):
  File "C:\Users\yy3\pi3-mini\measurements\pulsed.py", line 193, in _run
    tagger_0 = TimeTagger.Pulsed(self.n_bins, int(np.round(self.bin_width * 1000)), self.n_laser, 0, 2, 3)
               ^^^^^^^^^^^^^^^^^^^^^^^^^^^^^^^^^^^^^^^^^^^^^^^^^^^^^^^^^^^^^^^^^^^^^^^^^^^^^^^^^^^^^^^^^^^
  File "C:\Users\yy3\pi3-mini\hardware\time_tagger_swabian.py", line 30, in Pulsed
    return TimeDifferences(
           ^^^^^^^^^^^^^^^^
  File "C:\Program Files\Swabian Instruments\Time Tagger\driver\python\TimeTagger.py", line 4149, in __init__
    _TimeTagger.TimeDifferences_swiginit(self, _TimeTagger.new_TimeDifferences(*args, **kwargs))
                                               ^^^^^^^^^^^^^^^^^^^^^^^^^^^^^^^^^^^^^^^^^^^^^^^^
ValueError: n_histograms must be at least 1
2025-02-28 17:24:43,747 - diamond.<module> - INFO - Starting logger.
2025-02-28 17:24:44,402 - emod.start - INFO - Starting Job Manager.
2025-02-28 17:24:44,403 - cron.run - INFO - Starting Cron Daemon.
2025-02-28 17:24:53,418 - pulsed._run - ERROR - Something went wrong in pulsed loop.
Traceback (most recent call last):
  File "C:\Users\yy3\pi3-mini\measurements\pulsed.py", line 199, in _run
    if PulseGenerator().checkUnderflow():
       ^^^^^^^^^^^^^^^^^^^^^^^^^^^^^^^
AttributeError: 'PulseStreamer' object has no attribute 'checkUnderflow'
2025-02-28 17:26:43,128 - diamond.<module> - INFO - Starting logger.
2025-02-28 17:26:43,787 - emod.start - INFO - Starting Job Manager.
2025-02-28 17:26:43,788 - cron.run - INFO - Starting Cron Daemon.
2025-02-28 17:26:56,023 - pulsed._run - ERROR - Something went wrong in pulsed loop.
Traceback (most recent call last):
  File "C:\Users\yy3\pi3-mini\measurements\pulsed.py", line 224, in _run
    self.shut_down()
  File "C:\Users\yy3\pi3-mini\measurements\rabi.py", line 46, in shut_down
    ha.PulseGenerator().Light()
  File "C:\Users\yy3\pi3-mini\hardware\pulse_streamer.py", line 56, in Light
    self.pulse_streamer.constant([self.channel_map['aom']])
  File "D:\Anaconda\install\envs\pi3\Lib\site-packages\pulsestreamer\jrpc\pulse_streamer_jrpc.py", line 99, in constant
    output = self.convert_sequence_step((0, state[0], state[1], state[2]))
                                                      ~~~~~^^^
IndexError: list index out of range
2025-02-28 17:28:38,788 - diamond.<module> - INFO - Starting logger.
2025-02-28 17:28:39,453 - emod.start - INFO - Starting Job Manager.
2025-02-28 17:28:39,455 - cron.run - INFO - Starting Cron Daemon.
2025-02-28 17:40:24,543 - diamond.<module> - INFO - Starting logger.
2025-02-28 17:40:25,204 - emod.start - INFO - Starting Job Manager.
2025-02-28 17:40:25,205 - cron.run - INFO - Starting Cron Daemon.
