2023-08-22 15:10:35,510 - diamond.<module> - INFO - Starting logger.
2023-08-22 15:10:38,761 - emod.start - INFO - Starting Job Manager.
2023-08-22 15:10:38,764 - cron.run - INFO - Starting Cron Daemon.
2023-08-22 15:14:11,638 - diamond.<module> - INFO - Starting logger.
2023-08-22 15:14:13,187 - emod.start - INFO - Starting Job Manager.
2023-08-22 15:14:13,190 - cron.run - INFO - Starting Cron Daemon.
2023-08-22 15:23:31,642 - diamond.<module> - INFO - Starting logger.
2023-08-22 15:23:33,174 - emod.start - INFO - Starting Job Manager.
2023-08-22 15:23:33,177 - cron.run - INFO - Starting Cron Daemon.
2023-08-22 15:25:00,959 - diamond.<module> - INFO - Starting logger.
2023-08-22 15:25:02,381 - emod.start - INFO - Starting Job Manager.
2023-08-22 15:25:02,384 - cron.run - INFO - Starting Cron Daemon.
2023-08-22 15:26:29,620 - diamond.<module> - INFO - Starting logger.
2023-08-22 15:26:31,099 - emod.start - INFO - Starting Job Manager.
2023-08-22 15:26:31,102 - cron.run - INFO - Starting Cron Daemon.
2023-08-22 15:40:13,275 - diamond.<module> - INFO - Starting logger.
2023-08-22 15:40:14,992 - emod.start - INFO - Starting Job Manager.
2023-08-22 15:40:14,995 - cron.run - INFO - Starting Cron Daemon.
2023-08-22 15:41:02,252 - diamond.<module> - INFO - Starting logger.
2023-08-22 15:41:03,688 - emod.start - INFO - Starting Job Manager.
2023-08-22 15:41:03,691 - cron.run - INFO - Starting Cron Daemon.
2023-08-22 15:54:27,989 - diamond.<module> - INFO - Starting logger.
2023-08-22 15:54:29,625 - emod.start - INFO - Starting Job Manager.
2023-08-22 15:54:29,629 - cron.run - INFO - Starting Cron Daemon.
2023-08-22 15:55:10,956 - diamond.<module> - INFO - Starting logger.
2023-08-22 15:55:12,410 - emod.start - INFO - Starting Job Manager.
2023-08-22 15:55:12,414 - cron.run - INFO - Starting Cron Daemon.
2023-08-22 15:55:37,156 - trait_notifiers._log_exception - ERROR - Exception occurred in traits notification handler for object: <analysis.pulsed.PulsedAnalyzer object at 0x0000022FA3A5D210>, trait: fit, old value: <analysis.pulsed.PulsedFit object at 0x0000022FA4634590>, new value: <analysis.pulsed.PulsedFit object at 0x0000022FA665E160>
Traceback (most recent call last):
  File "C:\Users\Qubit\Anaconda3\envs\d3\lib\site-packages\traits\trait_notifiers.py", line 342, in __call__
    self.handler(*args)
  File "C:\Users\Qubit\src\d3\python3\analysis\pulsed.py", line 2476, in _fit_changed
    for key in plot.plots.keys():
RuntimeError: dictionary changed size during iteration
2023-08-22 15:56:21,449 - pulsed._run - ERROR - Something went wrong in pulsed loop.
Traceback (most recent call last):
  File "C:\Users\Qubit\src\d3\python3\measurements\pulsed.py", line 213, in _run
    self.count_data = self.old_count_data + tagger_0.getData()  + tagger_1.getData()
  File "C:\Users\Qubit\src\d3\python3\hardware\time_tagger_api.py", line 157, in getData
    data_received = self.socket.recv(2000000000).decode()
ConnectionResetError: [WinError 10054] An existing connection was forcibly closed by the remote host
2023-08-22 15:56:33,375 - diamond.<module> - INFO - Starting logger.
2023-08-22 15:56:34,918 - emod.start - INFO - Starting Job Manager.
2023-08-22 15:56:34,921 - cron.run - INFO - Starting Cron Daemon.
2023-08-22 15:56:45,788 - trait_notifiers._log_exception - ERROR - Exception occurred in traits notification handler for object: <analysis.pulsed.PulsedAnalyzer object at 0x000001EEF43A5A80>, trait: fit, old value: <analysis.pulsed.PulsedFit object at 0x000001EEF4D19940>, new value: <analysis.pulsed.PulsedFit object at 0x000001EEF7468540>
Traceback (most recent call last):
  File "C:\Users\Qubit\Anaconda3\envs\d3\lib\site-packages\traits\trait_notifiers.py", line 342, in __call__
    self.handler(*args)
  File "C:\Users\Qubit\src\d3\python3\analysis\pulsed.py", line 2476, in _fit_changed
    for key in plot.plots.keys():
RuntimeError: dictionary changed size during iteration
2023-08-22 16:00:35,244 - diamond.<module> - INFO - Starting logger.
2023-08-22 16:00:36,702 - emod.start - INFO - Starting Job Manager.
2023-08-22 16:00:36,705 - cron.run - INFO - Starting Cron Daemon.
2023-08-22 16:01:24,471 - diamond.<module> - INFO - Starting logger.
2023-08-22 16:01:25,903 - emod.start - INFO - Starting Job Manager.
2023-08-22 16:01:25,906 - cron.run - INFO - Starting Cron Daemon.
2023-08-22 16:01:42,586 - trait_notifiers._log_exception - ERROR - Exception occurred in traits notification handler for object: <analysis.pulsed.PulsedAnalyzer object at 0x0000027E696D43B0>, trait: fit, old value: <analysis.pulsed.PulsedFit object at 0x0000027E6A10D760>, new value: <analysis.pulsed.PulsedFit object at 0x0000027E6A35BAB0>
Traceback (most recent call last):
  File "C:\Users\Qubit\Anaconda3\envs\d3\lib\site-packages\traits\trait_notifiers.py", line 342, in __call__
    self.handler(*args)
  File "C:\Users\Qubit\src\d3\python3\analysis\pulsed.py", line 2476, in _fit_changed
    for key in plot.plots.keys():
RuntimeError: dictionary changed size during iteration
2023-08-22 16:03:18,565 - diamond.<module> - INFO - Starting logger.
2023-08-22 16:03:20,253 - emod.start - INFO - Starting Job Manager.
2023-08-22 16:03:20,256 - cron.run - INFO - Starting Cron Daemon.
2023-08-22 16:03:38,092 - diamond.<module> - INFO - Starting logger.
2023-08-22 16:03:39,528 - emod.start - INFO - Starting Job Manager.
2023-08-22 16:03:39,532 - cron.run - INFO - Starting Cron Daemon.
2023-08-22 16:03:53,076 - trait_notifiers._log_exception - ERROR - Exception occurred in traits notification handler for object: <analysis.pulsed.PulsedAnalyzer object at 0x000001D9F7A0E480>, trait: fit, old value: <analysis.pulsed.PulsedFit object at 0x000001D9F82C14E0>, new value: <analysis.pulsed.PulsedFit object at 0x000001D9FAA0CA90>
Traceback (most recent call last):
  File "C:\Users\Qubit\Anaconda3\envs\d3\lib\site-packages\traits\trait_notifiers.py", line 342, in __call__
    self.handler(*args)
  File "C:\Users\Qubit\src\d3\python3\analysis\pulsed.py", line 2476, in _fit_changed
    for key in plot.plots.keys():
RuntimeError: dictionary changed size during iteration
2023-08-22 16:07:16,954 - pulsed._run - ERROR - Something went wrong in pulsed loop.
Traceback (most recent call last):
  File "C:\Users\Qubit\src\d3\python3\measurements\pulsed.py", line 213, in _run
    self.count_data = self.old_count_data + tagger_0.getData()  + tagger_1.getData()
  File "C:\Users\Qubit\src\d3\python3\hardware\time_tagger_api.py", line 157, in getData
    data_received = self.socket.recv(2000000000).decode()
ConnectionResetError: [WinError 10054] An existing connection was forcibly closed by the remote host
2023-08-22 16:07:33,621 - diamond.<module> - INFO - Starting logger.
2023-08-22 16:07:35,248 - emod.start - INFO - Starting Job Manager.
2023-08-22 16:07:35,252 - cron.run - INFO - Starting Cron Daemon.
2023-08-22 16:07:49,074 - trait_notifiers._log_exception - ERROR - Exception occurred in traits notification handler for object: <analysis.pulsed.PulsedAnalyzer object at 0x0000017EB083F100>, trait: fit, old value: <analysis.pulsed.PulsedFit object at 0x0000017EB129CEA0>, new value: <analysis.pulsed.PulsedFit object at 0x0000017EB39F9440>
Traceback (most recent call last):
  File "C:\Users\Qubit\Anaconda3\envs\d3\lib\site-packages\traits\trait_notifiers.py", line 342, in __call__
    self.handler(*args)
  File "C:\Users\Qubit\src\d3\python3\analysis\pulsed.py", line 2476, in _fit_changed
    for key in plot.plots.keys():
RuntimeError: dictionary changed size during iteration
2023-08-22 16:08:15,800 - pulsed._run - ERROR - Something went wrong in pulsed loop.
Traceback (most recent call last):
  File "C:\Users\Qubit\src\d3\python3\measurements\pulsed.py", line 213, in _run
    self.count_data = self.old_count_data + tagger_0.getData()  + tagger_1.getData()
  File "C:\Users\Qubit\src\d3\python3\hardware\time_tagger_api.py", line 157, in getData
    data_received = self.socket.recv(2000000000).decode()
ConnectionResetError: [WinError 10054] An existing connection was forcibly closed by the remote host
2023-08-22 16:09:39,798 - diamond.<module> - INFO - Starting logger.
2023-08-22 16:09:41,446 - emod.start - INFO - Starting Job Manager.
2023-08-22 16:09:41,451 - cron.run - INFO - Starting Cron Daemon.
2023-08-22 16:10:24,439 - trait_notifiers._log_exception - ERROR - Exception occurred in traits notification handler for object: <analysis.pulsed.PulsedAnalyzer object at 0x00000252DA93E9D0>, trait: fit, old value: <analysis.pulsed.PulsedFit object at 0x00000252DB214590>, new value: <analysis.pulsed.PulsedFit object at 0x00000252DD97B290>
Traceback (most recent call last):
  File "C:\Users\Qubit\Anaconda3\envs\d3\lib\site-packages\traits\trait_notifiers.py", line 342, in __call__
    self.handler(*args)
  File "C:\Users\Qubit\src\d3\python3\analysis\pulsed.py", line 2476, in _fit_changed
    for key in plot.plots.keys():
RuntimeError: dictionary changed size during iteration
2023-08-22 16:10:30,190 - pulsed._run - ERROR - Something went wrong in pulsed loop.
Traceback (most recent call last):
  File "C:\Users\Qubit\src\d3\python3\measurements\pulsed.py", line 213, in _run
    self.count_data = self.old_count_data + tagger_0.getData()  + tagger_1.getData()
  File "C:\Users\Qubit\src\d3\python3\hardware\time_tagger_api.py", line 162, in getData
    result_object = json.loads(data_received)
  File "C:\Users\Qubit\Anaconda3\envs\d3\lib\json\__init__.py", line 346, in loads
    return _default_decoder.decode(s)
  File "C:\Users\Qubit\Anaconda3\envs\d3\lib\json\decoder.py", line 337, in decode
    obj, end = self.raw_decode(s, idx=_w(s, 0).end())
  File "C:\Users\Qubit\Anaconda3\envs\d3\lib\json\decoder.py", line 353, in raw_decode
    obj, end = self.scan_once(s, idx)
json.decoder.JSONDecodeError: Expecting ',' delimiter: line 1 column 130991 (char 130990)
2023-08-22 16:15:40,096 - diamond.<module> - INFO - Starting logger.
2023-08-22 16:15:41,844 - emod.start - INFO - Starting Job Manager.
2023-08-22 16:15:41,846 - cron.run - INFO - Starting Cron Daemon.
2023-08-22 16:15:53,193 - trait_notifiers._log_exception - ERROR - Exception occurred in traits notification handler for object: <analysis.pulsed.PulsedAnalyzer object at 0x000001D33CDD3D30>, trait: fit, old value: <analysis.pulsed.PulsedFit object at 0x000001D33E63BE70>, new value: <analysis.pulsed.PulsedFit object at 0x000001D340DDC090>
Traceback (most recent call last):
  File "C:\Users\Qubit\Anaconda3\envs\d3\lib\site-packages\traits\trait_notifiers.py", line 342, in __call__
    self.handler(*args)
  File "C:\Users\Qubit\src\d3\python3\analysis\pulsed.py", line 2476, in _fit_changed
    for key in plot.plots.keys():
RuntimeError: dictionary changed size during iteration
2023-08-22 16:15:58,573 - pulsed._run - ERROR - Something went wrong in pulsed loop.
Traceback (most recent call last):
  File "C:\Users\Qubit\src\d3\python3\measurements\pulsed.py", line 213, in _run
    self.count_data = self.old_count_data + tagger_0.getData()  + tagger_1.getData()
  File "C:\Users\Qubit\src\d3\python3\hardware\time_tagger_api.py", line 162, in getData
    result_object = json.loads(data_received)
  File "C:\Users\Qubit\Anaconda3\envs\d3\lib\json\__init__.py", line 346, in loads
    return _default_decoder.decode(s)
  File "C:\Users\Qubit\Anaconda3\envs\d3\lib\json\decoder.py", line 337, in decode
    obj, end = self.raw_decode(s, idx=_w(s, 0).end())
  File "C:\Users\Qubit\Anaconda3\envs\d3\lib\json\decoder.py", line 353, in raw_decode
    obj, end = self.scan_once(s, idx)
json.decoder.JSONDecodeError: Expecting ',' delimiter: line 1 column 130991 (char 130990)
2023-08-22 16:25:16,472 - diamond.<module> - INFO - Starting logger.
2023-08-22 16:25:18,030 - emod.start - INFO - Starting Job Manager.
2023-08-22 16:25:18,034 - cron.run - INFO - Starting Cron Daemon.
2023-08-22 16:25:31,694 - trait_notifiers._log_exception - ERROR - Exception occurred in traits notification handler for object: <analysis.pulsed.PulsedAnalyzer object at 0x000001C5899493A0>, trait: fit, old value: <analysis.pulsed.PulsedFit object at 0x000001C58A26D490>, new value: <analysis.pulsed.PulsedFit object at 0x000001C58C9E71F0>
Traceback (most recent call last):
  File "C:\Users\Qubit\Anaconda3\envs\d3\lib\site-packages\traits\trait_notifiers.py", line 342, in __call__
    self.handler(*args)
  File "C:\Users\Qubit\src\d3\python3\analysis\pulsed.py", line 2476, in _fit_changed
    for key in plot.plots.keys():
RuntimeError: dictionary changed size during iteration
2023-08-22 16:25:37,494 - pulsed._run - ERROR - Something went wrong in pulsed loop.
Traceback (most recent call last):
  File "C:\Users\Qubit\src\d3\python3\measurements\pulsed.py", line 213, in _run
    self.count_data = self.old_count_data + tagger_0.getData()  + tagger_1.getData()
  File "C:\Users\Qubit\src\d3\python3\hardware\time_tagger_api.py", line 162, in getData
    result_object = json.loads(data_received)
  File "C:\Users\Qubit\Anaconda3\envs\d3\lib\json\__init__.py", line 346, in loads
    return _default_decoder.decode(s)
  File "C:\Users\Qubit\Anaconda3\envs\d3\lib\json\decoder.py", line 337, in decode
    obj, end = self.raw_decode(s, idx=_w(s, 0).end())
  File "C:\Users\Qubit\Anaconda3\envs\d3\lib\json\decoder.py", line 353, in raw_decode
    obj, end = self.scan_once(s, idx)
json.decoder.JSONDecodeError: Expecting ',' delimiter: line 1 column 130991 (char 130990)
2023-08-22 16:26:01,387 - diamond.<module> - INFO - Starting logger.
2023-08-22 16:26:02,864 - emod.start - INFO - Starting Job Manager.
2023-08-22 16:26:02,867 - cron.run - INFO - Starting Cron Daemon.
2023-08-22 16:26:21,421 - trait_notifiers._log_exception - ERROR - Exception occurred in traits notification handler for object: <analysis.pulsed.PulsedAnalyzer object at 0x0000025A27AFB1A0>, trait: fit, old value: <analysis.pulsed.PulsedFit object at 0x0000025A297FC1D0>, new value: <analysis.pulsed.PulsedFit object at 0x0000025A2BFDA9D0>
Traceback (most recent call last):
  File "C:\Users\Qubit\Anaconda3\envs\d3\lib\site-packages\traits\trait_notifiers.py", line 342, in __call__
    self.handler(*args)
  File "C:\Users\Qubit\src\d3\python3\analysis\pulsed.py", line 2476, in _fit_changed
    for key in plot.plots.keys():
RuntimeError: dictionary changed size during iteration
2023-08-22 16:26:26,664 - pulsed._run - ERROR - Something went wrong in pulsed loop.
Traceback (most recent call last):
  File "C:\Users\Qubit\src\d3\python3\measurements\pulsed.py", line 213, in _run
    self.count_data = self.old_count_data + tagger_0.getData()  + tagger_1.getData()
  File "C:\Users\Qubit\src\d3\python3\hardware\time_tagger_api.py", line 162, in getData
    result_object = json.loads(data_received)
  File "C:\Users\Qubit\Anaconda3\envs\d3\lib\json\__init__.py", line 346, in loads
    return _default_decoder.decode(s)
  File "C:\Users\Qubit\Anaconda3\envs\d3\lib\json\decoder.py", line 337, in decode
    obj, end = self.raw_decode(s, idx=_w(s, 0).end())
  File "C:\Users\Qubit\Anaconda3\envs\d3\lib\json\decoder.py", line 353, in raw_decode
    obj, end = self.scan_once(s, idx)
json.decoder.JSONDecodeError: Expecting ',' delimiter: line 1 column 130991 (char 130990)
2023-08-22 16:32:51,349 - diamond.<module> - INFO - Starting logger.
2023-08-22 16:32:53,004 - emod.start - INFO - Starting Job Manager.
2023-08-22 16:32:53,008 - cron.run - INFO - Starting Cron Daemon.
2023-08-22 16:33:04,939 - trait_notifiers._log_exception - ERROR - Exception occurred in traits notification handler for object: <analysis.pulsed.PulsedAnalyzer object at 0x0000022AA85B7880>, trait: fit, old value: <analysis.pulsed.PulsedFit object at 0x0000022AA90E1210>, new value: <analysis.pulsed.PulsedFit object at 0x0000022AAB82C810>
Traceback (most recent call last):
  File "C:\Users\Qubit\Anaconda3\envs\d3\lib\site-packages\traits\trait_notifiers.py", line 342, in __call__
    self.handler(*args)
  File "C:\Users\Qubit\src\d3\python3\analysis\pulsed.py", line 2476, in _fit_changed
    for key in plot.plots.keys():
RuntimeError: dictionary changed size during iteration
2023-08-22 16:33:11,093 - pulsed._run - ERROR - Something went wrong in pulsed loop.
Traceback (most recent call last):
  File "C:\Users\Qubit\src\d3\python3\measurements\pulsed.py", line 213, in _run
    self.count_data = self.old_count_data + tagger_0.getData()  + tagger_1.getData()
  File "C:\Users\Qubit\src\d3\python3\hardware\time_tagger_api.py", line 165, in getData
    result_object = json.loads(data_received)
  File "C:\Users\Qubit\Anaconda3\envs\d3\lib\json\__init__.py", line 346, in loads
    return _default_decoder.decode(s)
  File "C:\Users\Qubit\Anaconda3\envs\d3\lib\json\decoder.py", line 337, in decode
    obj, end = self.raw_decode(s, idx=_w(s, 0).end())
  File "C:\Users\Qubit\Anaconda3\envs\d3\lib\json\decoder.py", line 353, in raw_decode
    obj, end = self.scan_once(s, idx)
json.decoder.JSONDecodeError: Expecting ',' delimiter: line 1 column 130991 (char 130990)
2023-08-22 16:34:38,133 - diamond.<module> - INFO - Starting logger.
2023-08-22 16:34:39,579 - emod.start - INFO - Starting Job Manager.
2023-08-22 16:34:39,582 - cron.run - INFO - Starting Cron Daemon.
2023-08-22 16:34:59,770 - trait_notifiers._log_exception - ERROR - Exception occurred in traits notification handler for object: <analysis.pulsed.PulsedAnalyzer object at 0x0000021C7E29BAB0>, trait: fit, old value: <analysis.pulsed.PulsedFit object at 0x0000021C7E93EF20>, new value: <analysis.pulsed.PulsedFit object at 0x0000021C81318EF0>
Traceback (most recent call last):
  File "C:\Users\Qubit\Anaconda3\envs\d3\lib\site-packages\traits\trait_notifiers.py", line 342, in __call__
    self.handler(*args)
  File "C:\Users\Qubit\src\d3\python3\analysis\pulsed.py", line 2476, in _fit_changed
    for key in plot.plots.keys():
RuntimeError: dictionary changed size during iteration
2023-08-22 16:39:40,198 - diamond.<module> - INFO - Starting logger.
2023-08-22 16:39:41,780 - emod.start - INFO - Starting Job Manager.
2023-08-22 16:39:41,783 - cron.run - INFO - Starting Cron Daemon.
2023-08-22 16:39:52,466 - trait_notifiers._log_exception - ERROR - Exception occurred in traits notification handler for object: <analysis.pulsed.PulsedAnalyzer object at 0x000001EEBB74C450>, trait: fit, old value: <analysis.pulsed.PulsedFit object at 0x000001EEBC2F0B80>, new value: <analysis.pulsed.PulsedFit object at 0x000001EEACAB8810>
Traceback (most recent call last):
  File "C:\Users\Qubit\Anaconda3\envs\d3\lib\site-packages\traits\trait_notifiers.py", line 342, in __call__
    self.handler(*args)
  File "C:\Users\Qubit\src\d3\python3\analysis\pulsed.py", line 2476, in _fit_changed
    for key in plot.plots.keys():
RuntimeError: dictionary changed size during iteration
2023-08-22 16:39:57,938 - pulsed._run - ERROR - Something went wrong in pulsed loop.
Traceback (most recent call last):
  File "C:\Users\Qubit\src\d3\python3\measurements\pulsed.py", line 213, in _run
    self.count_data = self.old_count_data + tagger_0.getData()  + tagger_1.getData()
  File "C:\Users\Qubit\src\d3\python3\hardware\time_tagger_api.py", line 165, in getData
    result_object = json.loads(data_received)
  File "C:\Users\Qubit\Anaconda3\envs\d3\lib\json\__init__.py", line 346, in loads
    return _default_decoder.decode(s)
  File "C:\Users\Qubit\Anaconda3\envs\d3\lib\json\decoder.py", line 337, in decode
    obj, end = self.raw_decode(s, idx=_w(s, 0).end())
  File "C:\Users\Qubit\Anaconda3\envs\d3\lib\json\decoder.py", line 353, in raw_decode
    obj, end = self.scan_once(s, idx)
json.decoder.JSONDecodeError: Expecting ',' delimiter: line 1 column 130991 (char 130990)
2023-08-22 16:42:45,991 - diamond.<module> - INFO - Starting logger.
2023-08-22 16:42:47,548 - emod.start - INFO - Starting Job Manager.
2023-08-22 16:42:47,552 - cron.run - INFO - Starting Cron Daemon.
2023-08-22 16:42:59,402 - pulsed._run - INFO - Underflow in pulse generator.
2023-08-22 16:43:00,827 - pulsed._run - INFO - Underflow in pulse generator.
2023-08-22 16:43:01,497 - pulsed._run - ERROR - Something went wrong in pulsed loop.
Traceback (most recent call last):
  File "C:\Users\Qubit\src\d3\python3\measurements\pulsed.py", line 213, in _run
    self.count_data = self.old_count_data + tagger_0.getData()  + tagger_1.getData()
  File "C:\Users\Qubit\src\d3\python3\hardware\time_tagger_api.py", line 157, in getData
    data_received = self.socket.recv(sys.maxint).decode()
AttributeError: module 'sys' has no attribute 'maxint'
2023-08-22 16:47:10,506 - diamond.<module> - INFO - Starting logger.
2023-08-22 16:47:12,202 - emod.start - INFO - Starting Job Manager.
2023-08-22 16:47:12,206 - cron.run - INFO - Starting Cron Daemon.
2023-08-22 16:47:59,625 - diamond.<module> - INFO - Starting logger.
2023-08-22 16:48:01,077 - emod.start - INFO - Starting Job Manager.
2023-08-22 16:48:01,080 - cron.run - INFO - Starting Cron Daemon.
2023-08-22 16:48:13,438 - trait_notifiers._log_exception - ERROR - Exception occurred in traits notification handler for object: <analysis.pulsed.PulsedAnalyzer object at 0x000001B4DD083650>, trait: fit, old value: <analysis.pulsed.PulsedFit object at 0x000001B4DDF2D990>, new value: <analysis.pulsed.PulsedFit object at 0x000001B4D69EBE20>
Traceback (most recent call last):
  File "C:\Users\Qubit\Anaconda3\envs\d3\lib\site-packages\traits\trait_notifiers.py", line 342, in __call__
    self.handler(*args)
  File "C:\Users\Qubit\src\d3\python3\analysis\pulsed.py", line 2476, in _fit_changed
    for key in plot.plots.keys():
RuntimeError: dictionary changed size during iteration
2023-08-22 16:49:10,493 - pulsed._run - ERROR - Something went wrong in pulsed loop.
Traceback (most recent call last):
  File "C:\Users\Qubit\src\d3\python3\measurements\pulsed.py", line 213, in _run
    self.count_data = self.old_count_data + tagger_0.getData()  + tagger_1.getData()
  File "C:\Users\Qubit\src\d3\python3\hardware\time_tagger_api.py", line 157, in getData
    data_received = self.socket.recv(2 ** 31 - 1).decode()
ConnectionResetError: [WinError 10054] An existing connection was forcibly closed by the remote host
2023-08-22 16:49:23,799 - diamond.<module> - INFO - Starting logger.
2023-08-22 16:49:25,332 - emod.start - INFO - Starting Job Manager.
2023-08-22 16:49:25,336 - cron.run - INFO - Starting Cron Daemon.
2023-08-22 16:49:39,111 - trait_notifiers._log_exception - ERROR - Exception occurred in traits notification handler for object: <analysis.pulsed.PulsedAnalyzer object at 0x0000021B758446D0>, trait: fit, old value: <analysis.pulsed.PulsedFit object at 0x0000021B76274BD0>, new value: <analysis.pulsed.PulsedFit object at 0x0000021B789D0720>
Traceback (most recent call last):
  File "C:\Users\Qubit\Anaconda3\envs\d3\lib\site-packages\traits\trait_notifiers.py", line 342, in __call__
    self.handler(*args)
  File "C:\Users\Qubit\src\d3\python3\analysis\pulsed.py", line 2476, in _fit_changed
    for key in plot.plots.keys():
RuntimeError: dictionary changed size during iteration
2023-08-22 16:49:45,292 - pulsed._run - ERROR - Something went wrong in pulsed loop.
Traceback (most recent call last):
  File "C:\Users\Qubit\src\d3\python3\measurements\pulsed.py", line 213, in _run
    self.count_data = self.old_count_data + tagger_0.getData()  + tagger_1.getData()
  File "C:\Users\Qubit\src\d3\python3\hardware\time_tagger_api.py", line 165, in getData
    result_object = json.loads(data_received)
  File "C:\Users\Qubit\Anaconda3\envs\d3\lib\json\__init__.py", line 346, in loads
    return _default_decoder.decode(s)
  File "C:\Users\Qubit\Anaconda3\envs\d3\lib\json\decoder.py", line 337, in decode
    obj, end = self.raw_decode(s, idx=_w(s, 0).end())
  File "C:\Users\Qubit\Anaconda3\envs\d3\lib\json\decoder.py", line 353, in raw_decode
    obj, end = self.scan_once(s, idx)
json.decoder.JSONDecodeError: Expecting ',' delimiter: line 1 column 130991 (char 130990)
2023-08-22 16:51:50,786 - diamond.<module> - INFO - Starting logger.
2023-08-22 16:51:52,219 - emod.start - INFO - Starting Job Manager.
2023-08-22 16:51:52,221 - cron.run - INFO - Starting Cron Daemon.
2023-08-22 16:52:05,468 - trait_notifiers._log_exception - ERROR - Exception occurred in traits notification handler for object: <analysis.pulsed.PulsedAnalyzer object at 0x0000023A429C0AE0>, trait: fit, old value: <analysis.pulsed.PulsedFit object at 0x0000023A43399300>, new value: <analysis.pulsed.PulsedFit object at 0x0000023A45AFDC60>
Traceback (most recent call last):
  File "C:\Users\Qubit\Anaconda3\envs\d3\lib\site-packages\traits\trait_notifiers.py", line 342, in __call__
    self.handler(*args)
  File "C:\Users\Qubit\src\d3\python3\analysis\pulsed.py", line 2476, in _fit_changed
    for key in plot.plots.keys():
RuntimeError: dictionary changed size during iteration
2023-08-22 16:52:10,726 - pulsed._run - ERROR - Something went wrong in pulsed loop.
Traceback (most recent call last):
  File "C:\Users\Qubit\src\d3\python3\measurements\pulsed.py", line 213, in _run
    self.count_data = self.old_count_data + tagger_0.getData()  + tagger_1.getData()
  File "C:\Users\Qubit\src\d3\python3\hardware\time_tagger_api.py", line 163, in getData
    result_object = json.loads(data_received)
  File "C:\Users\Qubit\Anaconda3\envs\d3\lib\json\__init__.py", line 346, in loads
    return _default_decoder.decode(s)
  File "C:\Users\Qubit\Anaconda3\envs\d3\lib\json\decoder.py", line 337, in decode
    obj, end = self.raw_decode(s, idx=_w(s, 0).end())
  File "C:\Users\Qubit\Anaconda3\envs\d3\lib\json\decoder.py", line 353, in raw_decode
    obj, end = self.scan_once(s, idx)
json.decoder.JSONDecodeError: Expecting ',' delimiter: line 1 column 130991 (char 130990)
2023-08-22 16:54:20,813 - diamond.<module> - INFO - Starting logger.
2023-08-22 16:54:22,267 - emod.start - INFO - Starting Job Manager.
2023-08-22 16:54:22,270 - cron.run - INFO - Starting Cron Daemon.
2023-08-22 16:54:33,171 - trait_notifiers._log_exception - ERROR - Exception occurred in traits notification handler for object: <analysis.pulsed.PulsedAnalyzer object at 0x000002AE2617DBC0>, trait: fit, old value: <analysis.pulsed.PulsedFit object at 0x000002AE26C650D0>, new value: <analysis.pulsed.PulsedFit object at 0x000002AE26C11C10>
Traceback (most recent call last):
  File "C:\Users\Qubit\Anaconda3\envs\d3\lib\site-packages\traits\trait_notifiers.py", line 342, in __call__
    self.handler(*args)
  File "C:\Users\Qubit\src\d3\python3\analysis\pulsed.py", line 2476, in _fit_changed
    for key in plot.plots.keys():
RuntimeError: dictionary changed size during iteration
2023-08-22 16:55:54,807 - pulsed._run - ERROR - Something went wrong in pulsed loop.
Traceback (most recent call last):
  File "C:\Users\Qubit\src\d3\python3\measurements\pulsed.py", line 213, in _run
    self.count_data = self.old_count_data + tagger_0.getData()  + tagger_1.getData()
  File "C:\Users\Qubit\src\d3\python3\hardware\time_tagger_api.py", line 156, in getData
    self.socket.sendall(json.dumps(command).encode())
ConnectionResetError: [WinError 10054] An existing connection was forcibly closed by the remote host
